Workbook

Sheet REPORTS
A1: SWATPlus-IAHRIS | AA1: Nat_F | AB1: Natural Flow
AA2: Alt_F | AB2: Altered Flow
B7: NATURAL FLOW CODE (Abbreviation): | E7: =CONCATENATE($AB$1," (",$AA$1,")") -> Natural Flow (Nat_F)
B8: ALTERED FLOW CODE (Abbreviation): | E8: =CONCATENATE($AB$2," (",$AA$2,")") -> Altered Flow (Alt_F)
B9: DATE: | E9: 18/05/2026
B12: (Point and Alteration identification inlcudes both thee code and description declared by the user).
B14: REPORTS : | G14: FIRST MONTH HYDROLOGIC YEAR: | K14: January
B16: REPORT 1: Nat_F: interannual variability | H16: REPORT 6a: Alt_F: anual flow rates duration curves
B17: REPORT 1a: Alt_F: interannual variability | H17: REPORT 6b: Nat_F and Alt_F: anual flow rates duration curves
B18: REPORT 1b: Nat_F and Alt_F: interannual variability | H18: REPORT 6c: Nat_F: monthly flow rates duration curves
B19: REPORT 2: Nat_F: intra-annual variability (statistics) | H19: REPORT 6d: Alt_F: monthly flow rates duration curves
B20: REPORT 2a: Nat_F: intra-annual variability (medians) | H20: REPORT 6e: Nat_F and Alt_F: monthly flow rates duration curves
B21: REPORT 3: Alt_F: intra-annual variability (statistics) | H21: REPORT 7c: IAH: habitual values with no-coetaneous data
B22: REPORT 3a: Alt_F: intra-annual variability (medians) | H22: REPORT 7d: IAH: floods and droughts
B23: REPORT 3b: Nat_F and Alt_F: intra-annual variability (medians) | H23: REPORT 8: Highly altered water bodies (P10-90)
B24: REPORT 3c: Nat_F and Alt_F: intra-annual variability (P10 - P90) | H24: REPORT 8b: Highly altered water bodies (IAH): no-coetaneous daily data
B25: REPORT 4: Nat_F: characterization with daily data | H25: REPORT 10c: Environmental sig. IAH: no-coetaneous daily data
B26: REPORT 5: Alt_F: characterization with daily data
B27: REPORT 6: Nat_F: anual flow rates duration curves
B29: DATA AVAILABLE AND DATA USED IN THE REPORTS:
B31: YEAR | C31: MONTHLY DATA | H31: DAILY DATA
C32: =$AA$1 -> Nat_F | E32: =$AA$2 -> Alt_F | G32: Contemporary | H32: =$AA$1 -> Nat_F | J32: =$AA$2 -> Alt_F | L32: Contemporary
C33: Available | D33: Used | E33: Available | F33: Used | H33: Available | I33: Used | J33: Available | K33: Used
B34: 1990-91 | C34: X | D34: X | H34: X | I34: X
B35: 1991-92 | C35: X | D35: X | H35: X | I35: X
B36: 1992-93 | C36: X | D36: X | H36: X | I36: X
B37: 1993-94 | C37: X | D37: X | H37: X | I37: X
B38: 1994-95 | C38: X | D38: X | H38: X | I38: X
B39: 1995-96 | C39: X | D39: X | H39: X | I39: X
B40: 1996-97 | C40: X | D40: X | H40: X | I40: X
B41: 1997-98 | C41: X | D41: X | H41: X | I41: X
B42: 1998-99 | C42: X | D42: X | H42: X | I42: X
B43: 1999-00 | C43: X | D43: X | H43: X | I43: X
B44: 2000-01 | C44: X | D44: X | H44: X | I44: X
B45: 2001-02 | C45: X | D45: X | H45: X | I45: X
... B54: 2010-11 | C54: X | D54: X | H54: X | I54: X
B55: 2011-12
B56: 2012-13
B57: 2013-14
B58: 2014-15
...

Sheet Informe nº1
B2: REPORT Nº 1 | E2: =UPPER(REPORTS!$AB$1) -> NATURAL FLOW
E3: CHARACTERIZATION OF THE INTERANNUAL VARIABILITY
B5: NATURAL FLOW CODE (Abbreviation): | E5: =REPORTS!E7 -> Natural Flow (Nat_F)
B6: ALTERED FLOW CODE (Abbreviation): | E6: =REPORTS!E8 -> Altered Flow (Alt_F) | U6: =CONCATENATE("ANNUAL CONTRIBUTIONS IN ",UPPER(REPORTS!$AB$1)," (hm³)") -> ANNUAL CONTRIBUTIONS IN NATURAL FLOW (hm³)
B7: DATE: | E7: 18/05/2026
B11: DATA | E11: RESULTS
B12: YEAR | C12: CONTRIBUTION
C13: hm3 | E13: CHARACTERIZATION OF INTERANNUAL VARIABILITY Wet years: Contributions are greater than or equal to the third quartile. Dry years: Contributions are less than or equal to the first quartile. Average years: Contributions fall between the first and third quartiles. | N13: TYPE OF YEAR | W13: AÑO | X13: =CONCATENATE("WET THRESHOLD ", REPORTS!$AA$1) -> WET THRESHOLD Nat_F | Y13: =UPPER(REPORTS!$AA$1) -> NAT_F | Z13: =CONCATENATE("DRY THRESHOLD ", REPORTS!$AA$1) -> DRY THRESHOLD Nat_F
B14: 1990-91 | C14: 92.207642 | N14: WET | P14: AVERAGE | R14: DRY | W14: =B14 -> 1990-91 | X14: =I$26 -> 105.73929 | Y14: =C14 -> 92.207642 | Z14: =I$23 -> 89.406956
B15: 1991-92 | C15: 97.979019 | N15: YEAR | O15: VOLUME | P15: YEAR | Q15: VOLUME | R15: YEAR | S15: VOLUME | W15: =B15 -> 1991-92 | X15: =I$26 -> 105.73929 | Y15: =C15 -> 97.979019 | Z15: =I$23 -> 89.406956
B16: 1992-93 | C16: 100.9414 | N16: 1995-96 | O16: 109.82182 | P16: 1990-91 | Q16: 92.207642 | R16: 1999-00 | S16: 82.448441 | W16: =B16 -> 1992-93 | X16: =I$26 -> 105.73929 | Y16: =C16 -> 100.9414 | Z16: =I$23 -> 89.406956
B17: 1993-94 | C17: 99.4795 | N17: 1996-97 | O17: 118.52345 | P17: 1991-92 | Q17: 97.979019 | R17: 2000-01 | S17: 73.9701 | W17: =B17 -> 1993-94 | X17: =I$26 -> 105.73929 | Y17: =C17 -> 99.4795 | Z17: =I$23 -> 89.406956
B18: 1994-95 | C18: 103.67399 | N18: 1997-98 | O18: 116.8333 | P18: 1992-93 | Q18: 100.9414 | R18: 2005-06 | S18: 87.014267 | W18: =B18 -> 1994-95 | X18: =I$26 -> 105.73929 | Y18: =C18 -> 103.67399 | Z18: =I$23 -> 89.406956
B19: 1995-96 | C19: 109.82182 | N19: 2003-04 | O19: 107.8046 | P19: 1993-94 | Q19: 99.4795 | R19: 2006-07 | S19: 88.203255 | W19: =B19 -> 1995-96 | X19: =I$26 -> 105.73929 | Y19: =C19 -> 109.82182 | Z19: =I$23 -> 89.406956
B20: 1996-97 | C20: 118.52345 | G20: DESCRIPTIVE STATISTICS | N20: 2008-09 | O20: 114.8331 | P20: 1994-95 | Q20: 103.67399 | R20: 2009-10 | S20: 78.004105 | W20: =B20 -> 1996-97 | X20: =I$26 -> 105.73929 | Y20: =C20 -> 118.52345 | Z20: =I$23 -> 89.406956
B21: 1997-98 | C21: 116.8333 | P21: 1998-99 | Q21: 102.62631 | W21: =B21 -> 1997-98 | X21: =I$26 -> 105.73929 | Y21: =C21 -> 116.8333 | Z21: =I$23 -> 89.406956
B22: 1998-99 | C22: 102.62631 | G22: MINIMUM | I22: =MIN(C14:C614) -> 73.9701 | J22: hm3 | P22: 2001-02 | Q22: 90.610657 | W22: =B22 -> 1998-99 | X22: =I$26 -> 105.73929 | Y22: =C22 -> 102.62631 | Z22: =I$23 -> 89.406956
B23: 1999-00 | C23: 82.448441 | G23: 75th percentile exceedance (P75) | I23: =_xlfn.PERCENTILE.EXC(C14:C614,0.25) -> 89.406956 | J23: hm3 | P23: 2002-03 | Q23: 93.292648 | W23: =B23 -> 1999-00 | X23: =I$26 -> 105.73929 | Y23: =C23 -> 82.448441 | Z23: =I$23 -> 89.406956
B24: 2000-01 | C24: 73.9701 | G24: 50th percentile exceedance (P50) | I24: =_xlfn.PERCENTILE.EXC(C14:C614,0.5) -> 99.4795 | J24: hm3 | P24: 2004-05 | Q24: 99.997284 | W24: =B24 -> 2000-01 | X24: =I$26 -> 105.73929 | Y24: =C24 -> 73.9701 | Z24: =I$23 -> 89.406956
B25: 2001-02 | C25: 90.610657 | G25: MEAN | I25: =AVERAGE(C14:C614) -> 97.722273 | J25: hm3 | P25: 2007-08 | Q25: 93.575554 | W25: =B25 -> 2001-02 | X25: =I$26 -> 105.73929 | Y25: =C25 -> 90.610657 | Z25: =I$23 -> 89.406956
B26: 2002-03 | C26: 93.292648 | G26: 25th percentile exceedance (P25) | I26: =_xlfn.PERCENTILE.EXC(C14:C614,0.75) -> 105.73929 | J26: hm3 | P26: 2010-11 | Q26: 100.32731 | W26: =B26 -> 2002-03 | X26: =I$26 -> 105.73929 | Y26: =C26 -> 93.292648 | Z26: =I$23 -> 89.406956
B27: 2003-04 | C27: 107.8046 | G27: MAXIMUM | I27: =MAX(C14:C614) -> 118.52345 | J27: hm3 | L27: =REPORTS!$AA$1 -> Nat_F | W27: =B27 -> 2003-04 | X27: =I$26 -> 105.73929 | Y27: =C27 -> 107.8046 | Z27: =I$23 -> 89.406956
B28: 2004-05 | C28: 99.997284 | G28: INTERQUARTILE RANGE | I28: =I26-I23 -> 16.332336 | J28: hm3 | W28: =B28 -> 2004-05 | X28: =I$26 -> 105.73929 | Y28: =C28 -> 99.997284 | Z28: =I$23 -> 89.406956
B29: 2005-06 | C29: 87.014267 | G29: Coefficient of variation | I29: =_xlfn.STDEV.S(C14:C614) -> 12.109999 | W29: =B29 -> 2005-06 | X29: =I$26 -> 105.73929 | Y29: =C29 -> 87.014267 | Z29: =I$23 -> 89.406956
B30: 2006-07 | C30: 88.203255 | G30: Coefficient of skewness | I30: =SKEW(C14:C614) -> -0.10027551 | W30: =B30 -> 2006-07 | X30: =I$26 -> 105.73929 | Y30: =C30 -> 88.203255 | Z30: =I$23 -> 89.406956
B31: 2007-08 | C31: 93.575554 | W31: =B31 -> 2007-08 | X31: =I$26 -> 105.73929 | Y31: =C31 -> 93.575554 | Z31: =I$23 -> 89.406956
B32: 2008-09 | C32: 114.8331 | W32: =B32 -> 2008-09 | X32: =I$26 -> 105.73929 | Y32: =C32 -> 114.8331 | Z32: =I$23 -> 89.406956
B33: 2009-10 | C33: 78.004105 | G33: =UPPER(REPORTS!$AA$1) -> NAT_F | W33: =B33 -> 2009-10 | X33: =I$26 -> 105.73929 | Y33: =C33 -> 78.004105 | Z33: =I$23 -> 89.406956
B34: 2010-11 | C34: 100.32731 | W34: =B34 -> 2010-11 | X34: =I$26 -> 105.73929 | Y34: =C34 -> 100.32731 | Z34: =I$23 -> 89.406956
W35: =B35 -> 0 | X35: =I$26 -> 105.73929 | Y35: =C35 -> 0 | Z35: =I$23 -> 89.406956
W36: =B36 -> 0 | X36: =I$26 -> 105.73929 | Y36: =C36 -> 0 | Z36: =I$23 -> 89.406956
W37: =B37 -> 0 | X37: =I$26 -> 105.73929 | Y37: =C37 -> 0 | Z37: =I$23 -> 89.406956
W38: =B38 -> 0 | X38: =I$26 -> 105.73929 | Y38: =C38 -> 0 | Z38: =I$23 -> 89.406956
W39: =B39 -> 0 | X39: =I$26 -> 105.73929 | Y39: =C39 -> 0 | Z39: =I$23 -> 89.406956
W40: =B40 -> 0 | X40: =I$26 -> 105.73929 | Y40: =C40 -> 0 | Z40: =I$23 -> 89.406956
W41: =B41 -> 0 | X41: =I$26 -> 105.73929 | Y41: =C41 -> 0 | Z41: =I$23 -> 89.406956
W42: =B42 -> 0 | X42: =I$26 -> 105.73929 | Y42: =C42 -> 0 | Z42: =I$23 -> 89.406956
W43: =B43 -> 0 | X43: =I$26 -> 105.73929 | Y43: =C43 -> 0 | Z43: =I$23 -> 89.406956
W44: =B44 -> 0 | X44: =I$26 -> 105.73929 | Y44: =C44 -> 0 | Z44: =I$23 -> 89.406956
W45: =B45 -> 0 | X45: =I$26 -> 105.73929 | Y45: =C45 -> 0 | Z45: =I$23 -> 89.406956
...

Sheet Informe nº1a
B2: REPORT Nº 1a | E2: =UPPER(REPORTS!$AB$2) -> ALTERED FLOW
E3: CHARACTERIZATION OF THE INTERANNUAL VARIABILITY
B5: NATURAL FLOW CODE (Abbreviation): | E5: =REPORTS!E7 -> Natural Flow (Nat_F)
B6: ALTERED FLOW CODE (Abbreviation): | E6: =REPORTS!E8 -> Altered Flow (Alt_F) | U6: =CONCATENATE("ANNUAL CONTRIBUTIONS IN ",UPPER(REPORTS!$AB$2)," (hm³)") -> ANNUAL CONTRIBUTIONS IN ALTERED FLOW (hm³)
B7: DATE: | E7: 18/05/2026
B11: DATA | E11: RESULTS
B12: YEAR | C12: CONTRIBUTION
C13: hm3 | E13: CHARACTERIZATION OF INTERANNUAL VARIABILITY Wet years: Contributions are greater than or equal to the third quartile. Dry years: Contributions are less than or equal to the first quartile. Average years: Contributions fall between the first and third quartiles. | N13: TYPE OF YEAR | Y13: AÑO | Z13: =UPPER(REPORTS!$AA$2) -> ALT_F | AA13: =CONCATENATE("WET THRESHOLD ", REPORTS!$AA$2) -> WET THRESHOLD Alt_F | AB13: =CONCATENATE("DRY THRESHOLD ", REPORTS!$AA$2) -> DRY THRESHOLD Alt_F
B14: 2080-81 | C14: 63.072636 | N14: WET | P14: AVERAGE | R14: DRY | Y14: =B14 -> 2080-81 | Z14: =C14 -> 63.072636 | AA14: =I$26 -> 61.180433 | AB14: =I$23 -> 47.812653
B15: 2081-82 | C15: 49.108883 | N15: YEAR | O15: VOLUME | P15: YEAR | Q15: VOLUME | R15: YEAR | S15: VOLUME | Y15: =B15 -> 2081-82 | Z15: =C15 -> 49.108883 | AA15: =I$26 -> 61.180433 | AB15: =I$23 -> 47.812653
B16: 2082-83 | C16: 53.830959 | N16: 2080-81 | O16: 63.072636 | P16: 2081-82 | Q16: 49.108883 | R16: 2089-90 | S16: 41.25753 | Y16: =B16 -> 2082-83 | Z16: =C16 -> 53.830959 | AA16: =I$26 -> 61.180433 | AB16: =I$23 -> 47.812653
B17: 2083-84 | C17: 70.150871 | N17: 2083-84 | O17: 70.150871 | P17: 2082-83 | Q17: 53.830959 | R17: 2091-92 | S17: 46.516422 | Y17: =B17 -> 2083-84 | Z17: =C17 -> 70.150871 | AA17: =I$26 -> 61.180433 | AB17: =I$23 -> 47.812653
B18: 2084-85 | C18: 70.799438 | N18: 2084-85 | O18: 70.799438 | P18: 2085-86 | Q18: 50.573441 | R18: 2092-93 | S18: 46.315048 | Y18: =B18 -> 2084-85 | Z18: =C18 -> 70.799438 | AA18: =I$26 -> 61.180433 | AB18: =I$23 -> 47.812653
B19: 2085-86 | C19: 50.573441 | N19: 2087-88 | O19: 66.402969 | P19: 2086-87 | Q19: 59.040455 | R19: 2095-96 | S19: 45.861164 | Y19: =B19 -> 2085-86 | Z19: =C19 -> 50.573441 | AA19: =I$26 -> 61.180433 | AB19: =I$23 -> 47.812653
B20: 2086-87 | C20: 59.040455 | G20: DESCRIPTIVE STATISTICS | N20: 2090-91 | O20: 62.096706 | P20: 2088-89 | Q20: 53.614456 | R20: 2100-01 | S20: 37.575661 | Y20: =B20 -> 2086-87 | Z20: =C20 -> 59.040455 | AA20: =I$26 -> 61.180433 | AB20: =I$23 -> 47.812653
B21: 2087-88 | C21: 66.402969 | P21: 2093-94 | Q21: 52.887718 | Y21: =B21 -> 2087-88 | Z21: =C21 -> 66.402969 | AA21: =I$26 -> 61.180433 | AB21: =I$23 -> 47.812653
B22: 2088-89 | C22: 53.614456 | G22: MINIMUM | I22: =MIN(C14:C614) -> 37.575661 | J22: hm3 | P22: 2094-95 | Q22: 50.793694 | Y22: =B22 -> 2088-89 | Z22: =C22 -> 53.614456 | AA22: =I$26 -> 61.180433 | AB22: =I$23 -> 47.812653
B23: 2089-90 | C23: 41.25753 | G23: 75th percentile exceedance (P75) | I23: =_xlfn.PERCENTILE.EXC(C14:C614,0.25) -> 47.812653 | J23: hm3 | P23: 2096-97 | Q23: 55.026752 | Y23: =B23 -> 2089-90 | Z23: =C23 -> 41.25753 | AA23: =I$26 -> 61.180433 | AB23: =I$23 -> 47.812653
B24: 2090-91 | C24: 62.096706 | G24: 50th percentile exceedance (P50) | I24: =_xlfn.PERCENTILE.EXC(C14:C614,0.5) -> 53.614456 | J24: hm3 | P24: 2097-98 | Q24: 59.504578 | Y24: =B24 -> 2090-91 | Z24: =C24 -> 62.096706 | AA24: =I$26 -> 61.180433 | AB24: =I$23 -> 47.812653
B25: 2091-92 | C25: 46.516422 | G25: MEAN | I25: =AVERAGE(C14:C614) -> 54.491479 | J25: hm3 | P25: 2098-99 | Q25: 60.26416 | Y25: =B25 -> 2091-92 | Z25: =C25 -> 46.516422 | AA25: =I$26 -> 61.180433 | AB25: =I$23 -> 47.812653
B26: 2092-93 | C26: 46.315048 | G26: 25th percentile exceedance (P25) | I26: =_xlfn.PERCENTILE.EXC(C14:C614,0.75) -> 61.180433 | J26: hm3 | L26: =REPORTS!$AA$1 -> Nat_F | P26: 2099-00 | Q26: 49.62751 | Y26: =B26 -> 2092-93 | Z26: =C26 -> 46.315048 | AA26: =I$26 -> 61.180433 | AB26: =I$23 -> 47.812653
B27: 2093-94 | C27: 52.887718 | G27: MAXIMUM | I27: =MAX(C14:C614) -> 70.799438 | J27: hm3 | L27: =REPORTS!$AA$2 -> Alt_F | Y27: =B27 -> 2093-94 | Z27: =C27 -> 52.887718 | AA27: =I$26 -> 61.180433 | AB27: =I$23 -> 47.812653
B28: 2094-95 | C28: 50.793694 | G28: INTERQUARTILE RANGE | I28: =I26-I23 -> 13.367781 | J28: hm3 | Y28: =B28 -> 2094-95 | Z28: =C28 -> 50.793694 | AA28: =I$26 -> 61.180433 | AB28: =I$23 -> 47.812653
B29: 2095-96 | C29: 45.861164 | G29: Coefficient of variation | I29: =_xlfn.STDEV.S(C14:C614) -> 8.9878057 | Y29: =B29 -> 2095-96 | Z29: =C29 -> 45.861164 | AA29: =I$26 -> 61.180433 | AB29: =I$23 -> 47.812653
B30: 2096-97 | C30: 55.026752 | G30: Coefficient of skewness | I30: =SKEW(C14:C614) -> 0.16059519 | Y30: =B30 -> 2096-97 | Z30: =C30 -> 55.026752 | AA30: =I$26 -> 61.180433 | AB30: =I$23 -> 47.812653
B31: 2097-98 | C31: 59.504578 | Y31: =B31 -> 2097-98 | Z31: =C31 -> 59.504578 | AA31: =I$26 -> 61.180433 | AB31: =I$23 -> 47.812653
B32: 2098-99 | C32: 60.26416 | Y32: =B32 -> 2098-99 | Z32: =C32 -> 60.26416 | AA32: =I$26 -> 61.180433 | AB32: =I$23 -> 47.812653
B33: 2099-00 | C33: 49.62751 | G33: =UPPER(REPORTS!$AA$2) -> ALT_F | Y33: =B33 -> 2099-00 | Z33: =C33 -> 49.62751 | AA33: =I$26 -> 61.180433 | AB33: =I$23 -> 47.812653
B34: 2100-01 | C34: 37.575661 | Y34: =B34 -> 2100-01 | Z34: =C34 -> 37.575661 | AA34: =I$26 -> 61.180433 | AB34: =I$23 -> 47.812653
Y35: =B35 -> 0 | Z35: =C35 -> 0 | AA35: =I$26 -> 61.180433 | AB35: =I$23 -> 47.812653
Y36: =B36 -> 0 | Z36: =C36 -> 0 | AA36: =I$26 -> 61.180433 | AB36: =I$23 -> 47.812653
Y37: =B37 -> 0 | Z37: =C37 -> 0 | AA37: =I$26 -> 61.180433 | AB37: =I$23 -> 47.812653
Y38: =B38 -> 0 | Z38: =C38 -> 0 | AA38: =I$26 -> 61.180433 | AB38: =I$23 -> 47.812653
Y39: =B39 -> 0 | Z39: =C39 -> 0 | AA39: =I$26 -> 61.180433 | AB39: =I$23 -> 47.812653
Y40: =B40 -> 0 | Z40: =C40 -> 0 | AA40: =I$26 -> 61.180433 | AB40: =I$23 -> 47.812653
Y41: =B41 -> 0 | Z41: =C41 -> 0 | AA41: =I$26 -> 61.180433 | AB41: =I$23 -> 47.812653
Y42: =B42 -> 0 | Z42: =C42 -> 0 | AA42: =I$26 -> 61.180433 | AB42: =I$23 -> 47.812653
Y43: =B43 -> 0 | Z43: =C43 -> 0 | AA43: =I$26 -> 61.180433 | AB43: =I$23 -> 47.812653
Y44: =B44 -> 0 | Z44: =C44 -> 0 | AA44: =I$26 -> 61.180433 | AB44: =I$23 -> 47.812653
Y45: =B45 -> 0 | Z45: =C45 -> 0 | AA45: =I$26 -> 61.180433 | AB45: =I$23 -> 47.812653
...

Sheet Informe nº 1b
B2: REPORT Nº 1b | F2: =CONCATENATE(UPPER(REPORTS!$AB$1)," Y ",UPPER(REPORTS!$AB$2)) -> NATURAL FLOW Y ALTERED FLOW
F3: CHARACTERIZATION OF THE INTERANNUAL VARIABILITY
B5: NATURAL FLOW CODE (Abbreviation): | F5: =REPORTS!E7 -> Natural Flow (Nat_F)
B6: ALTERED FLOW CODE (Abbreviation): | F6: =REPORTS!E8 -> Altered Flow (Alt_F) | U6: =CONCATENATE("ANNUAL CONTRIBUTIONS IN ",UPPER(REPORTS!$AB$1)," Y ",UPPER(REPORTS!$AB$2)," (hm³)") -> ANNUAL CONTRIBUTIONS IN NATURAL FLOW Y ALTERED FLOW (hm³)
B7: DATE: | F7: 18/05/2026
B11: CONTRIBUTION DATA | F11: RESULTS
B12: YEAR | C12: =REPORTS!$AA$1 -> Nat_F | D12: =REPORTS!$AA$2 -> Alt_F
C13: hm3 | D13: hm3 | F13: CHARACTERIZATION OF INTERANNUAL VARIABILITY Wet years: Contributions are greater than or equal to the third quartile. Dry years: Contributions are less than or equal to the first quartile. Average years: Contributions fall between the first and third quartiles. | Z13: AÑO | AA13: =UPPER(REPORTS!$AA$1) -> NAT_F | AB13: =CONCATENATE("UMBRAL HÚMEDO ", UPPER(REPORTS!$AA$1)) -> UMBRAL HÚMEDO NAT_F | AC13: =CONCATENATE("UMBRAL SECO ", UPPER(REPORTS!$AA$1)) -> UMBRAL SECO NAT_F | AD13: =UPPER(REPORTS!$AA$2) -> ALT_F | AE13: =CONCATENATE("UMBRAL HÚMEDO ", UPPER(REPORTS!$AA$2)) -> UMBRAL HÚMEDO ALT_F | AF13: =CONCATENATE("UMBRAL SECO ", UPPER(REPORTS!$AA$2)) -> UMBRAL SECO ALT_F
B14: 1990-91 | C14: 92.207642 | P14: =UPPER(REPORTS!$AA$1) -> NAT_F | Q14: =UPPER(REPORTS!$AA$2) -> ALT_F | Z14: =B14 -> 1990-91 | AA14: =C14 -> 92.207642 | AB14: =$J$24 -> 105.73929 | AC14: =$J$25 -> 89.406956 | AD14: =D14 -> 0 | AE14: =$K$24 -> 61.180433 | AF14: =$K$25 -> 47.812653
B15: 1991-92 | C15: 97.979019 | Z15: =B15 -> 1991-92 | AA15: =C15 -> 97.979019 | AB15: =$J$24 -> 105.73929 | AC15: =$J$25 -> 89.406956 | AD15: =D15 -> 0 | AE15: =$K$24 -> 61.180433 | AF15: =$K$25 -> 47.812653
B16: 1992-93 | C16: 100.9414 | Z16: =B16 -> 1992-93 | AA16: =C16 -> 100.9414 | AB16: =$J$24 -> 105.73929 | AC16: =$J$25 -> 89.406956 | AD16: =D16 -> 0 | AE16: =$K$24 -> 61.180433 | AF16: =$K$25 -> 47.812653
B17: 1993-94 | C17: 99.4795 | Z17: =B17 -> 1993-94 | AA17: =C17 -> 99.4795 | AB17: =$J$24 -> 105.73929 | AC17: =$J$25 -> 89.406956 | AD17: =D17 -> 0 | AE17: =$K$24 -> 61.180433 | AF17: =$K$25 -> 47.812653
B18: 1994-95 | C18: 103.67399 | Z18: =B18 -> 1994-95 | AA18: =C18 -> 103.67399 | AB18: =$J$24 -> 105.73929 | AC18: =$J$25 -> 89.406956 | AD18: =D18 -> 0 | AE18: =$K$24 -> 61.180433 | AF18: =$K$25 -> 47.812653
B19: 1995-96 | C19: 109.82182 | Z19: =B19 -> 1995-96 | AA19: =C19 -> 109.82182 | AB19: =$J$24 -> 105.73929 | AC19: =$J$25 -> 89.406956 | AD19: =D19 -> 0 | AE19: =$K$24 -> 61.180433 | AF19: =$K$25 -> 47.812653
B20: 1996-97 | C20: 118.52345 | Z20: =B20 -> 1996-97 | AA20: =C20 -> 118.52345 | AB20: =$J$24 -> 105.73929 | AC20: =$J$25 -> 89.406956 | AD20: =D20 -> 0 | AE20: =$K$24 -> 61.180433 | AF20: =$K$25 -> 47.812653
B21: 1997-98 | C21: 116.8333 | Z21: =B21 -> 1997-98 | AA21: =C21 -> 116.8333 | AB21: =$J$24 -> 105.73929 | AC21: =$J$25 -> 89.406956 | AD21: =D21 -> 0 | AE21: =$K$24 -> 61.180433 | AF21: =$K$25 -> 47.812653
B22: 1998-99 | C22: 102.62631 | H22: Thresholds for Year Types (hm3) | J22: =REPORTS!$AA$1 -> Nat_F | K22: =REPORTS!$AA$2 -> Alt_F | Z22: =B22 -> 1998-99 | AA22: =C22 -> 102.62631 | AB22: =$J$24 -> 105.73929 | AC22: =$J$25 -> 89.406956 | AD22: =D22 -> 0 | AE22: =$K$24 -> 61.180433 | AF22: =$K$25 -> 47.812653
B23: 1999-00 | C23: 82.448441 | J23: hm3 | K23: hm3 | Z23: =B23 -> 1999-00 | AA23: =C23 -> 82.448441 | AB23: =$J$24 -> 105.73929 | AC23: =$J$25 -> 89.406956 | AD23: =D23 -> 0 | AE23: =$K$24 -> 61.180433 | AF23: =$K$25 -> 47.812653
B24: 2000-01 | C24: 73.9701 | H24: WET YEAR | J24: =_xlfn.PERCENTILE.EXC(C14:C614,0.75) -> 105.73929 | K24: =_xlfn.PERCENTILE.EXC(D14:D614,0.75) -> 61.180433 | Z24: =B24 -> 2000-01 | AA24: =C24 -> 73.9701 | AB24: =$J$24 -> 105.73929 | AC24: =$J$25 -> 89.406956 | AD24: =D24 -> 0 | AE24: =$K$24 -> 61.180433 | AF24: =$K$25 -> 47.812653
B25: 2001-02 | C25: 90.610657 | H25: DRY YEAR | J25: =_xlfn.PERCENTILE.EXC(C14:C615,0.25) -> 89.406956 | K25: =_xlfn.PERCENTILE.EXC(D14:D615,0.25) -> 47.812653 | Z25: =B25 -> 2001-02 | AA25: =C25 -> 90.610657 | AB25: =$J$24 -> 105.73929 | AC25: =$J$25 -> 89.406956 | AD25: =D25 -> 0 | AE25: =$K$24 -> 61.180433 | AF25: =$K$25 -> 47.812653
B26: 2002-03 | C26: 93.292648 | M26: =REPORTS!$AA$1 -> Nat_F | Z26: =B26 -> 2002-03 | AA26: =C26 -> 93.292648 | AB26: =$J$24 -> 105.73929 | AC26: =$J$25 -> 89.406956 | AD26: =D26 -> 0 | AE26: =$K$24 -> 61.180433 | AF26: =$K$25 -> 47.812653
B27: 2003-04 | C27: 107.8046 | Z27: =B27 -> 2003-04 | AA27: =C27 -> 107.8046 | AB27: =$J$24 -> 105.73929 | AC27: =$J$25 -> 89.406956 | AD27: =D27 -> 0 | AE27: =$K$24 -> 61.180433 | AF27: =$K$25 -> 47.812653
B28: 2004-05 | C28: 99.997284 | Z28: =B28 -> 2004-05 | AA28: =C28 -> 99.997284 | AB28: =$J$24 -> 105.73929 | AC28: =$J$25 -> 89.406956 | AD28: =D28 -> 0 | AE28: =$K$24 -> 61.180433 | AF28: =$K$25 -> 47.812653
B29: 2005-06 | C29: 87.014267 | Z29: =B29 -> 2005-06 | AA29: =C29 -> 87.014267 | AB29: =$J$24 -> 105.73929 | AC29: =$J$25 -> 89.406956 | AD29: =D29 -> 0 | AE29: =$K$24 -> 61.180433 | AF29: =$K$25 -> 47.812653
B30: 2006-07 | C30: 88.203255 | Z30: =B30 -> 2006-07 | AA30: =C30 -> 88.203255 | AB30: =$J$24 -> 105.73929 | AC30: =$J$25 -> 89.406956 | AD30: =D30 -> 0 | AE30: =$K$24 -> 61.180433 | AF30: =$K$25 -> 47.812653
B31: 2007-08 | C31: 93.575554 | Z31: =B31 -> 2007-08 | AA31: =C31 -> 93.575554 | AB31: =$J$24 -> 105.73929 | AC31: =$J$25 -> 89.406956 | AD31: =D31 -> 0 | AE31: =$K$24 -> 61.180433 | AF31: =$K$25 -> 47.812653
B32: 2008-09 | C32: 114.8331 | Z32: =B32 -> 2008-09 | AA32: =C32 -> 114.8331 | AB32: =$J$24 -> 105.73929 | AC32: =$J$25 -> 89.406956 | AD32: =D32 -> 0 | AE32: =$K$24 -> 61.180433 | AF32: =$K$25 -> 47.812653
B33: 2009-10 | C33: 78.004105 | Z33: =B33 -> 2009-10 | AA33: =C33 -> 78.004105 | AB33: =$J$24 -> 105.73929 | AC33: =$J$25 -> 89.406956 | AD33: =D33 -> 0 | AE33: =$K$24 -> 61.180433 | AF33: =$K$25 -> 47.812653
B34: 2010-11 | C34: 100.32731 | Z34: =B34 -> 2010-11 | AA34: =C34 -> 100.32731 | AB34: =$J$24 -> 105.73929 | AC34: =$J$25 -> 89.406956 | AD34: =D34 -> 0 | AE34: =$K$24 -> 61.180433 | AF34: =$K$25 -> 47.812653
B35: 2080-81 | D35: 63.072636 | Z35: =B35 -> 2080-81 | AA35: =C35 -> 0 | AB35: =$J$24 -> 105.73929 | AC35: =$J$25 -> 89.406956 | AD35: =D35 -> 63.072636 | AE35: =$K$24 -> 61.180433 | AF35: =$K$25 -> 47.812653
B36: 2081-82 | D36: 49.108883 | Z36: =B36 -> 2081-82 | AA36: =C36 -> 0 | AB36: =$J$24 -> 105.73929 | AC36: =$J$25 -> 89.406956 | AD36: =D36 -> 49.108883 | AE36: =$K$24 -> 61.180433 | AF36: =$K$25 -> 47.812653
B37: 2082-83 | D37: 53.830959 | Z37: =B37 -> 2082-83 | AA37: =C37 -> 0 | AB37: =$J$24 -> 105.73929 | AC37: =$J$25 -> 89.406956 | AD37: =D37 -> 53.830959 | AE37: =$K$24 -> 61.180433 | AF37: =$K$25 -> 47.812653
B38: 2083-84 | D38: 70.150871 | Z38: =B38 -> 2083-84 | AA38: =C38 -> 0 | AB38: =$J$24 -> 105.73929 | AC38: =$J$25 -> 89.406956 | AD38: =D38 -> 70.150871 | AE38: =$K$24 -> 61.180433 | AF38: =$K$25 -> 47.812653
B39: 2084-85 | D39: 70.799438 | Z39: =B39 -> 2084-85 | AA39: =C39 -> 0 | AB39: =$J$24 -> 105.73929 | AC39: =$J$25 -> 89.406956 | AD39: =D39 -> 70.799438 | AE39: =$K$24 -> 61.180433 | AF39: =$K$25 -> 47.812653
B40: 2085-86 | D40: 50.573441 | Z40: =B40 -> 2085-86 | AA40: =C40 -> 0 | AB40: =$J$24 -> 105.73929 | AC40: =$J$25 -> 89.406956 | AD40: =D40 -> 50.573441 | AE40: =$K$24 -> 61.180433 | AF40: =$K$25 -> 47.812653
B41: 2086-87 | D41: 59.040455 | Z41: =B41 -> 2086-87 | AA41: =C41 -> 0 | AB41: =$J$24 -> 105.73929 | AC41: =$J$25 -> 89.406956 | AD41: =D41 -> 59.040455 | AE41: =$K$24 -> 61.180433 | AF41: =$K$25 -> 47.812653
B42: 2087-88 | D42: 66.402969 | Z42: =B42 -> 2087-88 | AA42: =C42 -> 0 | AB42: =$J$24 -> 105.73929 | AC42: =$J$25 -> 89.406956 | AD42: =D42 -> 66.402969 | AE42: =$K$24 -> 61.180433 | AF42: =$K$25 -> 47.812653
B43: 2088-89 | D43: 53.614456 | Z43: =B43 -> 2088-89 | AA43: =C43 -> 0 | AB43: =$J$24 -> 105.73929 | AC43: =$J$25 -> 89.406956 | AD43: =D43 -> 53.614456 | AE43: =$K$24 -> 61.180433 | AF43: =$K$25 -> 47.812653
B44: 2089-90 | D44: 41.25753 | Z44: =B44 -> 2089-90 | AA44: =C44 -> 0 | AB44: =$J$24 -> 105.73929 | AC44: =$J$25 -> 89.406956 | AD44: =D44 -> 41.25753 | AE44: =$K$24 -> 61.180433 | AF44: =$K$25 -> 47.812653
B45: 2090-91 | D45: 62.096706 | Z45: =B45 -> 2090-91 | AA45: =C45 -> 0 | AB45: =$J$24 -> 105.73929 | AC45: =$J$25 -> 89.406956 | AD45: =D45 -> 62.096706 | AE45: =$K$24 -> 61.180433 | AF45: =$K$25 -> 47.812653
...

Sheet Informe nº 2
B2: REPORT Nº 2 | E2: =UPPER(REPORTS!$AB$1) -> NATURAL FLOW | S2: MONTHLY CONTRIBUTIONS (hm3)
E3: CHARACTERIZATION OF THE INTRA-ANNUAL VARIABILITY (STATISTICS) | Q3: STATISTICS | S3: =C14 -> Jan | T3: =D14 -> Feb | U3: =E14 -> Mar | V3: =F14 -> Apr | W3: =G14 -> May | X3: =H14 -> Jun | Y3: =I14 -> Jul | Z3: =J14 -> Aug | ... AD3: =N14 -> Dec
Q4: MINIMUM | S4: =MIN(C12:C612) -> 9.4067135 | T4: =MIN(D12:D612) -> 8.7175865 | U4: =MIN(E12:E612) -> 8.0987911 | V4: =MIN(F12:F612) -> 8.6432829 | W4: =MIN(G12:G612) -> 8.5523901 | X4: =MIN(H12:H612) -> 3.371388 | Y4: =MIN(I12:I612) -> 0.87557751 | Z4: =MIN(J12:J612) -> 0.41032231 | ... AD4: =MIN(N12:N612) -> 5.365181 | AF4: =CONCATENATE("MONTHLY CONTRIBUTIONS IN ",UPPER(REPORTS!$AB$1)," (hm³)") -> MONTHLY CONTRIBUTIONS IN NATURAL FLOW (hm³)
B5: NATURAL FLOW CODE (Abbreviation): | E5: =REPORTS!E7 -> Natural Flow (Nat_F) | Q5: 75th percentile exceedance (P75) | S5: =_xlfn.PERCENTILE.EXC(C12:C612,0.25) -> 12.734236 | T5: =_xlfn.PERCENTILE.EXC(D12:D612,0.25) -> 10.280736 | U5: =_xlfn.PERCENTILE.EXC(E12:E612,0.25) -> 9.8122759 | V5: =_xlfn.PERCENTILE.EXC(F12:F612,0.25) -> 11.105682 | W5: =_xlfn.PERCENTILE.EXC(G12:G612,0.25) -> 10.983644 | X5: =_xlfn.PERCENTILE.EXC(H12:H612,0.25) -> 4.309628 | Y5: =_xlfn.PERCENTILE.EXC(I12:I612,0.25) -> 1.0327262 | Z5: =_xlfn.PERCENTILE.EXC(J12:J612,0.25) -> 0.45033842 | ... AD5: =_xlfn.PERCENTILE.EXC(N12:N612,0.25) -> 12.483418
B6: ALTERED FLOW CODE (Abbreviation): | E6: =REPORTS!E8 -> Altered Flow (Alt_F) | Q6: 50th percentile exceedance (P50) | S6: =_xlfn.PERCENTILE.EXC(C12:C612,0.5) -> 14.372986 | T6: =_xlfn.PERCENTILE.EXC(D12:D612,0.5) -> 12.314159 | U6: =_xlfn.PERCENTILE.EXC(E12:E612,0.5) -> 11.537078 | V6: =_xlfn.PERCENTILE.EXC(F12:F612,0.5) -> 13.178936 | W6: =_xlfn.PERCENTILE.EXC(G12:G612,0.5) -> 13.492225 | X6: =_xlfn.PERCENTILE.EXC(H12:H612,0.5) -> 4.8620734 | Y6: =_xlfn.PERCENTILE.EXC(I12:I612,0.5) -> 1.1413268 | Z6: =_xlfn.PERCENTILE.EXC(J12:J612,0.5) -> 0.48838466 | ... AD6: =_xlfn.PERCENTILE.EXC(N12:N612,0.5) -> 14.289956
B7: DATE: | E7: 18/05/2026 | Q7: MEAN | S7: =AVERAGE(C12:C612) -> 14.578268 | T7: =AVERAGE(D12:D612) -> 11.757654 | U7: =AVERAGE(E12:E612) -> 11.808453 | V7: =AVERAGE(F12:F612) -> 12.994753 | W7: =AVERAGE(G12:G612) -> 13.640536 | X7: =AVERAGE(H12:H612) -> 5.2164593 | Y7: =AVERAGE(I12:I612) -> 1.1932494 | Z7: =AVERAGE(J12:J612) -> 0.5054828 | ... AD7: =AVERAGE(N12:N612) -> 14.761971
Q8: 25th percentile exceedance (P25) | S8: =_xlfn.PERCENTILE.EXC(C12:C612,0.75) -> 16.780563 | T8: =_xlfn.PERCENTILE.EXC(D12:D612,0.75) -> 12.938918 | U8: =_xlfn.PERCENTILE.EXC(E12:E612,0.75) -> 12.809879 | V8: =_xlfn.PERCENTILE.EXC(F12:F612,0.75) -> 14.612659 | W8: =_xlfn.PERCENTILE.EXC(G12:G612,0.75) -> 16.170277 | X8: =_xlfn.PERCENTILE.EXC(H12:H612,0.75) -> 6.3332067 | Y8: =_xlfn.PERCENTILE.EXC(I12:I612,0.75) -> 1.3297781 | Z8: =_xlfn.PERCENTILE.EXC(J12:J612,0.75) -> 0.55520201 | ... AD8: =_xlfn.PERCENTILE.EXC(N12:N612,0.75) -> 17.754292
Q9: MAXIMUM | S9: =MAX(C12:C612) -> 19.403191 | T9: =MAX(D12:D612) -> 14.505524 | U9: =MAX(E12:E612) -> 16.793915 | V9: =MAX(F12:F612) -> 16.607893 | W9: =MAX(G12:G612) -> 19.9711 | X9: =MAX(H12:H612) -> 7.2789402 | Y9: =MAX(I12:I612) -> 1.5791848 | Z9: =MAX(J12:J612) -> 0.65658814 | ... AD9: =MAX(N12:N612) -> 23.475832
Q10: INTERQUARTILE RANGE | S10: =S8-S5 -> 4.0463271 | T10: =T8-T5 -> 2.6581817 | U10: =U8-U5 -> 2.9976029 | V10: =V8-V5 -> 3.5069761 | W10: =W8-W5 -> 5.1866331 | X10: =X8-X5 -> 2.0235786 | Y10: =Y8-Y5 -> 0.29705197 | Z10: =Z8-Z5 -> 0.10486358 | ... AD10: =AD8-AD5 -> 5.270874
Q11: Coefficient of variation | S11: =_xlfn.STDEV.S(C12:C612) -> 2.6370521 | T11: =_xlfn.STDEV.S(D12:D612) -> 1.6541842 | U11: =_xlfn.STDEV.S(E12:E612) -> 2.4213605 | V11: =_xlfn.STDEV.S(F12:F612) -> 2.0807962 | W11: =_xlfn.STDEV.S(G12:G612) -> 2.98735 | X11: =_xlfn.STDEV.S(H12:H612) -> 1.14691 | Y11: =_xlfn.STDEV.S(I12:I612) -> 0.22014095 | Z11: =_xlfn.STDEV.S(J12:J612) -> 0.070695671 | ... AD11: =_xlfn.STDEV.S(N12:N612) -> 3.8946307
Q12: Coefficient of skewness | S12: =SKEW(C12:C612) -> -0.047853954 | T12: =SKEW(D12:D612) -> -0.41758739 | U12: =SKEW(E12:E612) -> 0.59400394 | V12: =SKEW(F12:F612) -> -0.16773001 | W12: =SKEW(G12:G612) -> 0.34115392 | X12: =SKEW(H12:H612) -> 0.29078529 | Y12: =SKEW(I12:I612) -> 0.49959535 | Z12: =SKEW(J12:J612) -> 0.73086299 | ... AD12: =SKEW(N12:N612) -> -0.078175774
B13: YEAR | C13: MONTHLY CONTRIBUTION (hm3) | O13: Extreme variability
C14: Jan | D14: Feb | E14: Mar | F14: Apr | G14: May | H14: Jun | I14: Jul | J14: Aug | K14: Sep | L14: Oct | M14: Nov | N14: Dec
B15: 1990 | C15: 13.545962 | D15: 11.747461 | E15: 12.202013 | F15: 15.218756 | G15: 12.126928 | H15: 4.6181841 | I15: 1.0645087 | J15: 0.46942842 | K15: 0.80473828 | L15: 2.321594 | M15: 5.1065431 | N15: 12.981514 | O15: =MAX(C15:N15) - MIN(C15:N15) -> 14.749327 | S15: RELATIVE FREQUENCIES
B16: 1991 | C16: 16.794256 | D16: 8.7175865 | E16: 16.352671 | F16: 13.571713 | G16: 13.358129 | H16: 5.177279 | I16: 1.1413268 | J16: 0.47246975 | K16: 0.37693983 | L16: 2.9658785 | M16: 7.3560948 | N16: 11.694672 | O16: =MAX(C16:N16) - MIN(C16:N16) -> 16.417316 | S16: =C14 -> Jan | T16: =D14 -> Feb | U16: =E14 -> Mar | V16: =F14 -> Apr | W16: =G14 -> May | X16: =H14 -> Jun | Y16: =I14 -> Jul | Z16: =J14 -> Aug | ... AD16: =N14 -> Dec
B17: 1992 | C17: 14.503277 | D17: 14.505524 | E17: 13.186452 | F17: 15.144795 | G17: 10.68984 | H17: 4.7894454 | I17: 1.1124948 | J17: 0.50251102 | K17: 0.47787845 | L17: 3.2715962 | M17: 8.4676332 | N17: 14.289956 | O17: =MAX(C17:N17) - MIN(C17:N17) -> 14.666917 | Q17: Maximum monthly contribution | S17: 0.19047619 | T17: 0 | U17: 0 | V17: 0.095238097 | W17: 0.19047619 | X17: 0 | Y17: 0 | Z17: 0 | AA17: 0 | AB17: 0 | AC17: 0 | AD17: 0.52380955
B18: 1993 | C18: 11.507702 | D18: 10.80674 | E18: 11.173593 | F18: 11.190614 | G18: 14.02704 | H18: 6.1683812 | I18: 1.3343531 | J18: 0.50165564 | K18: 0.36047891 | L18: 2.5453959 | M18: 10.988697 | N18: 18.874857 | O18: =MAX(C18:N18) - MIN(C18:N18) -> 18.514378 | Q18: Minimum monthly contribution | S18: 0 | T18: 0 | U18: 0 | V18: 0 | W18: 0 | X18: 0 | Y18: 0 | Z18: 0.5714286 | AA18: 0.42857143 | AB18: 0 | AC18: 0 | AD18: 0
B19: 1994 | C19: 16.381269 | D19: 13.207364 | E19: 11.537078 | F19: 13.448418 | G19: 17.726603 | H19: 7.0030651 | I19: 1.5718752 | J19: 0.61138374 | K19: 0.5150218 | L19: 1.6431723 | M19: 7.3767447 | N19: 12.651982 | O19: =MAX(C19:N19) - MIN(C19:N19) -> 17.211581
B20: 1995 | C20: 14.372986 | D20: 12.314159 | E20: 11.501395 | F20: 16.607893 | G20: 17.286999 | H20: 5.3214188 | I20: 1.2905395 | J20: 0.56764787 | K20: 0.53283745 | L20: 3.4835958 | M20: 8.5855684 | N20: 17.95677 | O20: =MAX(C20:N20) - MIN(C20:N20) -> 17.423932
B21: 1996 | C21: 18.485537 | D21: 12.886473 | E21: 12.409114 | F21: 10.667462 | G21: 13.492225 | H21: 5.9097428 | I21: 1.3046919 | J21: 0.54275614 | K21: 0.65722752 | L21: 5.4806113 | M21: 13.21177 | N21: 23.475832 | O21: =MAX(C21:N21) - MIN(C21:N21) -> 22.933076
B22: 1997 | C22: 16.76687 | D22: 12.991363 | E22: 10.935993 | F22: 14.86071 | G22: 19.9711 | H22: 6.65731 | I22: 1.5115422 | J22: 0.65658814 | K22: 0.78495264 | L22: 3.4473598 | M22: 10.493453 | N22: 17.756063 | O22: =MAX(C22:N22) - MIN(C22:N22) -> 19.314512
B23: 1998 | C23: 16.904593 | D23: 9.3760405 | E23: 8.5016727 | F23: 13.178936 | G23: 17.462219 | H23: 6.6775098 | I23: 1.5369612 | J23: 0.58144611 | K23: 0.5254935 | L23: 3.1476302 | M23: 6.9812932 | N23: 17.75252 | O23: =MAX(C23:N23) - MIN(C23:N23) -> 17.227026
B24: 1999 | C24: 19.403191 | D24: 10.653553 | E24: 12.433306 | F24: 10.550736 | G24: 11.038378 | H24: 5.3754282 | I24: 1.207224 | J24: 0.48838466 | K24: 0.4870109 | L24: 1.589682 | M24: 3.8563695 | N24: 5.365181 | O24: =MAX(C24:N24) - MIN(C24:N24) -> 18.91618
B25: 2000 | C25: 10.41984 | D25: 9.1706696 | E25: 8.0987911 | F25: 11.020751 | G25: 10.928909 | H25: 3.933758 | I25: 0.90668172 | J25: 0.41032231 | K25: 0.4252755 | L25: 2.7790215 | M25: 3.5612266 | N25: 12.314853 | O25: =MAX(C25:N25) - MIN(C25:N25) -> 11.90453
B26: 2001 | C26: 12.521435 | D26: 9.9079189 | E26: 13.780455 | F26: 13.580006 | G26: 16.230497 | H26: 4.7081518 | I26: 1.1666421 | J26: 0.51961827 | K26: 0.59523553 | L26: 2.5890536 | M26: 3.9991102 | N26: 11.012544 | O26: =MAX(C26:N26) - MIN(C26:N26) -> 15.710879
B27: 2002 | C27: 12.004761 | D27: 12.065674 | E27: 11.633415 | F27: 12.795236 | G27: 14.458782 | H27: 4.1161914 | I27: 1.0267947 | J27: 0.47445694 | K27: 0.80536896 | L27: 4.2686615 | M27: 5.6060805 | N27: 14.037235 | O27: =MAX(C27:N27) - MIN(C27:N27) -> 13.984325
B28: 2003 | C28: 14.361582 | D28: 12.844657 | E28: 11.399529 | F28: 10.590135 | G28: 11.383891 | H28: 4.5030646 | I28: 1.0359792 | J28: 0.44395769 | K28: 0.79137206 | L28: 5.9615393 | M28: 14.821142 | N28: 19.667751 | O28: =MAX(C28:N28) - MIN(C28:N28) -> 19.223794
B29: 2004 | C29: 15.121555 | D29: 13.573873 | E29: 15.863386 | F29: 14.364607 | G29: 9.6323051 | H29: 3.371388 | I29: 0.87557751 | J29: 0.4218221 | K29: 0.55556667 | L29: 2.1859288 | M29: 7.0796847 | N29: 16.951593 | O29: =MAX(C29:N29) - MIN(C29:N29) -> 16.529771
B30: 2005 | C30: 14.138063 | D30: 13.655259 | E30: 10.16833 | F30: 13.152759 | G30: 10.912752 | H30: 4.8456836 | I30: 1.0596788 | J30: 0.45671916 | K30: 0.31015095 | L30: 2.2616324 | M30: 5.658371 | N30: 10.394871 | O30: =MAX(C30:N30) - MIN(C30:N30) -> 13.827912
... B35: 2010 | C35: 14.898817 | D35: 12.743915 | E35: 12.223959 | F35: 14.221006 | G35: 14.071795 | H35: 4.0915499 | I35: 1.0294732 | J35: 0.48090243 | K35: 0.95061606 | L35: 2.9164324 | M35: 6.2513862 | N35: 16.447449 | O35: =MAX(C35:N35) - MIN(C35:N35) -> 15.966546
R46: =UPPER(REPORTS!$AA$1) -> NAT_F

Sheet Informe nº2a
B2: REPORT Nº 2a | D2: =UPPER(REPORTS!$AB$1) -> NATURAL FLOW
D3: CHARACTERIZATION OF THE INTRA-ANNUAL VARIABILITY (MEDIANS)
B5: NATURAL FLOW CODE (Abbreviation): | E5: =REPORTS!E7 -> Natural Flow (Nat_F)
B6: ALTERED FLOW CODE (Abbreviation): | E6: =REPORTS!E8 -> Altered Flow (Alt_F) | U6: =CONCATENATE("MEDIANS CONTRIBUTIONS IN ",UPPER(REPORTS!$AB$1)," (hm³)") -> MEDIANS CONTRIBUTIONS IN NATURAL FLOW (hm³)
B7: DATE: | E7: 18/05/2026
B12: RESULTS
B14: MONTHLY | C14: MEDIANS CONTRIBUTIONS (hm3) | F14: DAILY MEDIAN FLOW RATE (m3/s) | J14: WEIGHTED YEAR | L14: Atypical distribution (*)
C15: WET | D15: AVERAGE | E15: DRY | F15: WET | G15: AVERAGE | H15: DRY | J15: MEDIANS CONTRIBUTIONS (hm3) | K15: DAILY MEDIAN FLOW RATE (m3/s)
B17: ='Informe nº 2'!C14 -> Jan | C17: 18.099506 | D17: 14.372986 | E17: 11.507702 | F17: =IF($B17="OCT",C17*0.373, IF($B17="NOV",C17*0.386,IF($B17="DIC",C17*0.373,IF($B17="ENE",C17*0.373,IF($B17="FEB",C17*0.413,IF($B17="MAR",C17*0.373,IF($B17="ABR",C17*0.386,IF($B17="MAY",C17*0.373,IF($B17="JUN",C17*0.386,IF($B17="JUL",C17*0.373,IF($B17="AGO",C17*0.373,IF($B17="SEP",C17*0.386,"")))))))))))) | G17: =IF($D17="#","#",IF($B17="OCT",D17*0.373, IF($B17="NOV",D17*0.386,IF($B17="DIC",D17*0.373,IF($B17="ENE",D17*0.373,IF($B17="FEB",D17*0.413,IF($B17="MAR",D17*0.373,IF($B17="ABR",D17*0.386,IF($B17="MAY",D17*0.373,IF($B17="JUN",D17*0.386,IF($B17="JUL",D17*0.373,IF($B17="AGO",D17*0.373,IF($B17="SEP",D17*0.386,""))))))))))))) | H17: =IF($B17="OCT",E17*0.373, IF($B17="NOV",E17*0.386,IF($B17="DIC",E17*0.373,IF($B17="ENE",E17*0.373,IF($B17="FEB",E17*0.413,IF($B17="MAR",E17*0.373,IF($B17="ABR",E17*0.386,IF($B17="MAY",E17*0.373,IF($B17="JUN",E17*0.386,IF($B17="JUL",E17*0.373,IF($B17="AGO",E17*0.373,IF($B17="SEP",E17*0.386,"")))))))))))) | K17: =IF($B17="OCT",J17*0.373, IF($B17="NOV",J17*0.386,IF($B17="DIC",J17*0.373,IF($B17="ENE",J17*0.373,IF($B17="FEB",J17*0.413,IF($B17="MAR",J17*0.373,IF($B17="ABR",J17*0.386,IF($B17="MAY",J17*0.373,IF($B17="JUN",J17*0.386,IF($B17="JUL",J17*0.373,IF($B17="AGO",J17*0.373,IF($B17="SEP",J17*0.386,""))))))))))))
B18: ='Informe nº 2'!D14 -> Feb | C18: 13.573873 | D18: 12.314159 | E18: 9.3760405 | F18: =IF($B18="OCT",C18*0.373, IF($B18="NOV",C18*0.386,IF($B18="DIC",C18*0.373,IF($B18="ENE",C18*0.373,IF($B18="FEB",C18*0.413,IF($B18="MAR",C18*0.373,IF($B18="ABR",C18*0.386,IF($B18="MAY",C18*0.373,IF($B18="JUN",C18*0.386,IF($B18="JUL",C18*0.373,IF($B18="AGO",C18*0.373,IF($B18="SEP",C18*0.386,"")))))))))))) -> 5.6060094 | G18: =IF($D18="#","#",IF($B18="OCT",D18*0.373, IF($B18="NOV",D18*0.386,IF($B18="DIC",D18*0.373,IF($B18="ENE",D18*0.373,IF($B18="FEB",D18*0.413,IF($B18="MAR",D18*0.373,IF($B18="ABR",D18*0.386,IF($B18="MAY",D18*0.373,IF($B18="JUN",D18*0.386,IF($B18="JUL",D18*0.373,IF($B18="AGO",D18*0.373,IF($B18="SEP",D18*0.386,""))))))))))))) -> 5.0857478 | H18: =IF($B18="OCT",E18*0.373, IF($B18="NOV",E18*0.386,IF($B18="DIC",E18*0.373,IF($B18="ENE",E18*0.373,IF($B18="FEB",E18*0.413,IF($B18="MAR",E18*0.373,IF($B18="ABR",E18*0.386,IF($B18="MAY",E18*0.373,IF($B18="JUN",E18*0.386,IF($B18="JUL",E18*0.373,IF($B18="AGO",E18*0.373,IF($B18="SEP",E18*0.386,"")))))))))))) -> 3.8723047 | K18: =IF($B18="OCT",J18*0.373, IF($B18="NOV",J18*0.386,IF($B18="DIC",J18*0.373,IF($B18="ENE",J18*0.373,IF($B18="FEB",J18*0.413,IF($B18="MAR",J18*0.373,IF($B18="ABR",J18*0.386,IF($B18="MAY",J18*0.373,IF($B18="JUN",J18*0.386,IF($B18="JUL",J18*0.373,IF($B18="AGO",J18*0.373,IF($B18="SEP",J18*0.386,"")))))))))))) -> 0
B19: ='Informe nº 2'!E14 -> Mar | C19: 15.863386 | D19: 11.537078 | E19: 9.1410341 | F19: =IF($B19="OCT",C19*0.373, IF($B19="NOV",C19*0.386,IF($B19="DIC",C19*0.373,IF($B19="ENE",C19*0.373,IF($B19="FEB",C19*0.413,IF($B19="MAR",C19*0.373,IF($B19="ABR",C19*0.386,IF($B19="MAY",C19*0.373,IF($B19="JUN",C19*0.386,IF($B19="JUL",C19*0.373,IF($B19="AGO",C19*0.373,IF($B19="SEP",C19*0.386,"")))))))))))) -> 5.917043 | G19: =IF($D19="#","#",IF($B19="OCT",D19*0.373, IF($B19="NOV",D19*0.386,IF($B19="DIC",D19*0.373,IF($B19="ENE",D19*0.373,IF($B19="FEB",D19*0.413,IF($B19="MAR",D19*0.373,IF($B19="ABR",D19*0.386,IF($B19="MAY",D19*0.373,IF($B19="JUN",D19*0.386,IF($B19="JUL",D19*0.373,IF($B19="AGO",D19*0.373,IF($B19="SEP",D19*0.386,""))))))))))))) -> 4.3033301 | H19: =IF($B19="OCT",E19*0.373, IF($B19="NOV",E19*0.386,IF($B19="DIC",E19*0.373,IF($B19="ENE",E19*0.373,IF($B19="FEB",E19*0.413,IF($B19="MAR",E19*0.373,IF($B19="ABR",E19*0.386,IF($B19="MAY",E19*0.373,IF($B19="JUN",E19*0.386,IF($B19="JUL",E19*0.373,IF($B19="AGO",E19*0.373,IF($B19="SEP",E19*0.386,"")))))))))))) -> 3.4096057 | K19: =IF($B19="OCT",J19*0.373, IF($B19="NOV",J19*0.386,IF($B19="DIC",J19*0.373,IF($B19="ENE",J19*0.373,IF($B19="FEB",J19*0.413,IF($B19="MAR",J19*0.373,IF($B19="ABR",J19*0.386,IF($B19="MAY",J19*0.373,IF($B19="JUN",J19*0.386,IF($B19="JUL",J19*0.373,IF($B19="AGO",J19*0.373,IF($B19="SEP",J19*0.386,"")))))))))))) -> 0
B20: ='Informe nº 2'!F14 -> Apr | C20: 15.218756 | D20: 13.178936 | E20: 10.590135 | F20: =IF($B20="OCT",C20*0.373, IF($B20="NOV",C20*0.386,IF($B20="DIC",C20*0.373,IF($B20="ENE",C20*0.373,IF($B20="FEB",C20*0.413,IF($B20="MAR",C20*0.373,IF($B20="ABR",C20*0.386,IF($B20="MAY",C20*0.373,IF($B20="JUN",C20*0.386,IF($B20="JUL",C20*0.373,IF($B20="AGO",C20*0.373,IF($B20="SEP",C20*0.386,"")))))))))))) | G20: =IF($D20="#","#",IF($B20="OCT",D20*0.373, IF($B20="NOV",D20*0.386,IF($B20="DIC",D20*0.373,IF($B20="ENE",D20*0.373,IF($B20="FEB",D20*0.413,IF($B20="MAR",D20*0.373,IF($B20="ABR",D20*0.386,IF($B20="MAY",D20*0.373,IF($B20="JUN",D20*0.386,IF($B20="JUL",D20*0.373,IF($B20="AGO",D20*0.373,IF($B20="SEP",D20*0.386,""))))))))))))) | H20: =IF($B20="OCT",E20*0.373, IF($B20="NOV",E20*0.386,IF($B20="DIC",E20*0.373,IF($B20="ENE",E20*0.373,IF($B20="FEB",E20*0.413,IF($B20="MAR",E20*0.373,IF($B20="ABR",E20*0.386,IF($B20="MAY",E20*0.373,IF($B20="JUN",E20*0.386,IF($B20="JUL",E20*0.373,IF($B20="AGO",E20*0.373,IF($B20="SEP",E20*0.386,"")))))))))))) | K20: =IF($B20="OCT",J20*0.373, IF($B20="NOV",J20*0.386,IF($B20="DIC",J20*0.373,IF($B20="ENE",J20*0.373,IF($B20="FEB",J20*0.413,IF($B20="MAR",J20*0.373,IF($B20="ABR",J20*0.386,IF($B20="MAY",J20*0.373,IF($B20="JUN",J20*0.386,IF($B20="JUL",J20*0.373,IF($B20="AGO",J20*0.373,IF($B20="SEP",J20*0.386,""))))))))))))
B21: ='Informe nº 2'!G14 -> May | C21: 17.462219 | D21: 13.492225 | E21: 10.68984 | F21: =IF($B21="OCT",C21*0.373, IF($B21="NOV",C21*0.386,IF($B21="DIC",C21*0.373,IF($B21="ENE",C21*0.373,IF($B21="FEB",C21*0.413,IF($B21="MAR",C21*0.373,IF($B21="ABR",C21*0.386,IF($B21="MAY",C21*0.373,IF($B21="JUN",C21*0.386,IF($B21="JUL",C21*0.373,IF($B21="AGO",C21*0.373,IF($B21="SEP",C21*0.386,"")))))))))))) -> 6.5134078 | G21: =IF($D21="#","#",IF($B21="OCT",D21*0.373, IF($B21="NOV",D21*0.386,IF($B21="DIC",D21*0.373,IF($B21="ENE",D21*0.373,IF($B21="FEB",D21*0.413,IF($B21="MAR",D21*0.373,IF($B21="ABR",D21*0.386,IF($B21="MAY",D21*0.373,IF($B21="JUN",D21*0.386,IF($B21="JUL",D21*0.373,IF($B21="AGO",D21*0.373,IF($B21="SEP",D21*0.386,""))))))))))))) -> 5.0325998 | H21: =IF($B21="OCT",E21*0.373, IF($B21="NOV",E21*0.386,IF($B21="DIC",E21*0.373,IF($B21="ENE",E21*0.373,IF($B21="FEB",E21*0.413,IF($B21="MAR",E21*0.373,IF($B21="ABR",E21*0.386,IF($B21="MAY",E21*0.373,IF($B21="JUN",E21*0.386,IF($B21="JUL",E21*0.373,IF($B21="AGO",E21*0.373,IF($B21="SEP",E21*0.386,"")))))))))))) -> 3.9873104 | K21: =IF($B21="OCT",J21*0.373, IF($B21="NOV",J21*0.386,IF($B21="DIC",J21*0.373,IF($B21="ENE",J21*0.373,IF($B21="FEB",J21*0.413,IF($B21="MAR",J21*0.373,IF($B21="ABR",J21*0.386,IF($B21="MAY",J21*0.373,IF($B21="JUN",J21*0.386,IF($B21="JUL",J21*0.373,IF($B21="AGO",J21*0.373,IF($B21="SEP",J21*0.386,"")))))))))))) -> 0
B22: ='Informe nº 2'!H14 -> Jun | C22: 6.6775098 | D22: 4.8620734 | E22: 3.933758 | F22: =IF($B22="OCT",C22*0.373, IF($B22="NOV",C22*0.386,IF($B22="DIC",C22*0.373,IF($B22="ENE",C22*0.373,IF($B22="FEB",C22*0.413,IF($B22="MAR",C22*0.373,IF($B22="ABR",C22*0.386,IF($B22="MAY",C22*0.373,IF($B22="JUN",C22*0.386,IF($B22="JUL",C22*0.373,IF($B22="AGO",C22*0.373,IF($B22="SEP",C22*0.386,"")))))))))))) -> 2.5775188 | G22: =IF($D22="#","#",IF($B22="OCT",D22*0.373, IF($B22="NOV",D22*0.386,IF($B22="DIC",D22*0.373,IF($B22="ENE",D22*0.373,IF($B22="FEB",D22*0.413,IF($B22="MAR",D22*0.373,IF($B22="ABR",D22*0.386,IF($B22="MAY",D22*0.373,IF($B22="JUN",D22*0.386,IF($B22="JUL",D22*0.373,IF($B22="AGO",D22*0.373,IF($B22="SEP",D22*0.386,""))))))))))))) -> 1.8767603 | H22: =IF($B22="OCT",E22*0.373, IF($B22="NOV",E22*0.386,IF($B22="DIC",E22*0.373,IF($B22="ENE",E22*0.373,IF($B22="FEB",E22*0.413,IF($B22="MAR",E22*0.373,IF($B22="ABR",E22*0.386,IF($B22="MAY",E22*0.373,IF($B22="JUN",E22*0.386,IF($B22="JUL",E22*0.373,IF($B22="AGO",E22*0.373,IF($B22="SEP",E22*0.386,"")))))))))))) -> 1.5184306 | K22: =IF($B22="OCT",J22*0.373, IF($B22="NOV",J22*0.386,IF($B22="DIC",J22*0.373,IF($B22="ENE",J22*0.373,IF($B22="FEB",J22*0.413,IF($B22="MAR",J22*0.373,IF($B22="ABR",J22*0.386,IF($B22="MAY",J22*0.373,IF($B22="JUN",J22*0.386,IF($B22="JUL",J22*0.373,IF($B22="AGO",J22*0.373,IF($B22="SEP",J22*0.386,"")))))))))))) -> 0
B23: ='Informe nº 2'!I14 -> Jul | C23: 1.5369612 | D23: 1.1413268 | E23: 0.92626852 | F23: =IF($B23="OCT",C23*0.373, IF($B23="NOV",C23*0.386,IF($B23="DIC",C23*0.373,IF($B23="ENE",C23*0.373,IF($B23="FEB",C23*0.413,IF($B23="MAR",C23*0.373,IF($B23="ABR",C23*0.386,IF($B23="MAY",C23*0.373,IF($B23="JUN",C23*0.386,IF($B23="JUL",C23*0.373,IF($B23="AGO",C23*0.373,IF($B23="SEP",C23*0.386,"")))))))))))) -> 0.57328653 | G23: =IF($D23="#","#",IF($B23="OCT",D23*0.373, IF($B23="NOV",D23*0.386,IF($B23="DIC",D23*0.373,IF($B23="ENE",D23*0.373,IF($B23="FEB",D23*0.413,IF($B23="MAR",D23*0.373,IF($B23="ABR",D23*0.386,IF($B23="MAY",D23*0.373,IF($B23="JUN",D23*0.386,IF($B23="JUL",D23*0.373,IF($B23="AGO",D23*0.373,IF($B23="SEP",D23*0.386,""))))))))))))) -> 0.42571489 | H23: =IF($B23="OCT",E23*0.373, IF($B23="NOV",E23*0.386,IF($B23="DIC",E23*0.373,IF($B23="ENE",E23*0.373,IF($B23="FEB",E23*0.413,IF($B23="MAR",E23*0.373,IF($B23="ABR",E23*0.386,IF($B23="MAY",E23*0.373,IF($B23="JUN",E23*0.386,IF($B23="JUL",E23*0.373,IF($B23="AGO",E23*0.373,IF($B23="SEP",E23*0.386,"")))))))))))) -> 0.34549816 | K23: =IF($B23="OCT",J23*0.373, IF($B23="NOV",J23*0.386,IF($B23="DIC",J23*0.373,IF($B23="ENE",J23*0.373,IF($B23="FEB",J23*0.413,IF($B23="MAR",J23*0.373,IF($B23="ABR",J23*0.386,IF($B23="MAY",J23*0.373,IF($B23="JUN",J23*0.386,IF($B23="JUL",J23*0.373,IF($B23="AGO",J23*0.373,IF($B23="SEP",J23*0.386,"")))))))))))) -> 0
B24: ='Informe nº 2'!J14 -> Aug | C24: 0.61138374 | D24: 0.48838466 | E24: 0.42326501 | F24: =IF($B24="OCT",C24*0.373, IF($B24="NOV",C24*0.386,IF($B24="DIC",C24*0.373,IF($B24="ENE",C24*0.373,IF($B24="FEB",C24*0.413,IF($B24="MAR",C24*0.373,IF($B24="ABR",C24*0.386,IF($B24="MAY",C24*0.373,IF($B24="JUN",C24*0.386,IF($B24="JUL",C24*0.373,IF($B24="AGO",C24*0.373,IF($B24="SEP",C24*0.386,"")))))))))))) | G24: =IF($D24="#","#",IF($B24="OCT",D24*0.373, IF($B24="NOV",D24*0.386,IF($B24="DIC",D24*0.373,IF($B24="ENE",D24*0.373,IF($B24="FEB",D24*0.413,IF($B24="MAR",D24*0.373,IF($B24="ABR",D24*0.386,IF($B24="MAY",D24*0.373,IF($B24="JUN",D24*0.386,IF($B24="JUL",D24*0.373,IF($B24="AGO",D24*0.373,IF($B24="SEP",D24*0.386,""))))))))))))) | H24: =IF($B24="OCT",E24*0.373, IF($B24="NOV",E24*0.386,IF($B24="DIC",E24*0.373,IF($B24="ENE",E24*0.373,IF($B24="FEB",E24*0.413,IF($B24="MAR",E24*0.373,IF($B24="ABR",E24*0.386,IF($B24="MAY",E24*0.373,IF($B24="JUN",E24*0.386,IF($B24="JUL",E24*0.373,IF($B24="AGO",E24*0.373,IF($B24="SEP",E24*0.386,"")))))))))))) | K24: =IF($B24="OCT",J24*0.373, IF($B24="NOV",J24*0.386,IF($B24="DIC",J24*0.373,IF($B24="ENE",J24*0.373,IF($B24="FEB",J24*0.413,IF($B24="MAR",J24*0.373,IF($B24="ABR",J24*0.386,IF($B24="MAY",J24*0.373,IF($B24="JUN",J24*0.386,IF($B24="JUL",J24*0.373,IF($B24="AGO",J24*0.373,IF($B24="SEP",J24*0.386,""))))))))))))
B25: ='Informe nº 2'!K14 -> Sep | C25: 0.87912011 | D25: 0.55524099 | E25: 0.37693983 | F25: =IF($B25="OCT",C25*0.373, IF($B25="NOV",C25*0.386,IF($B25="DIC",C25*0.373,IF($B25="ENE",C25*0.373,IF($B25="FEB",C25*0.413,IF($B25="MAR",C25*0.373,IF($B25="ABR",C25*0.386,IF($B25="MAY",C25*0.373,IF($B25="JUN",C25*0.386,IF($B25="JUL",C25*0.373,IF($B25="AGO",C25*0.373,IF($B25="SEP",C25*0.386,"")))))))))))) -> 0.33934036 | G25: =IF($D25="#","#",IF($B25="OCT",D25*0.373, IF($B25="NOV",D25*0.386,IF($B25="DIC",D25*0.373,IF($B25="ENE",D25*0.373,IF($B25="FEB",D25*0.413,IF($B25="MAR",D25*0.373,IF($B25="ABR",D25*0.386,IF($B25="MAY",D25*0.373,IF($B25="JUN",D25*0.386,IF($B25="JUL",D25*0.373,IF($B25="AGO",D25*0.373,IF($B25="SEP",D25*0.386,""))))))))))))) -> 0.21432302 | H25: =IF($B25="OCT",E25*0.373, IF($B25="NOV",E25*0.386,IF($B25="DIC",E25*0.373,IF($B25="ENE",E25*0.373,IF($B25="FEB",E25*0.413,IF($B25="MAR",E25*0.373,IF($B25="ABR",E25*0.386,IF($B25="MAY",E25*0.373,IF($B25="JUN",E25*0.386,IF($B25="JUL",E25*0.373,IF($B25="AGO",E25*0.373,IF($B25="SEP",E25*0.386,"")))))))))))) -> 0.14549878 | K25: =IF($B25="OCT",J25*0.373, IF($B25="NOV",J25*0.386,IF($B25="DIC",J25*0.373,IF($B25="ENE",J25*0.373,IF($B25="FEB",J25*0.413,IF($B25="MAR",J25*0.373,IF($B25="ABR",J25*0.386,IF($B25="MAY",J25*0.373,IF($B25="JUN",J25*0.386,IF($B25="JUL",J25*0.373,IF($B25="AGO",J25*0.373,IF($B25="SEP",J25*0.386,"")))))))))))) -> 0
B26: ='Informe nº 2'!L14 -> Oct | C26: 4.2686615 | D26: 2.9164324 | E26: 2.1859288 | F26: =IF($B26="OCT",C26*0.373, IF($B26="NOV",C26*0.386,IF($B26="DIC",C26*0.373,IF($B26="ENE",C26*0.373,IF($B26="FEB",C26*0.413,IF($B26="MAR",C26*0.373,IF($B26="ABR",C26*0.386,IF($B26="MAY",C26*0.373,IF($B26="JUN",C26*0.386,IF($B26="JUL",C26*0.373,IF($B26="AGO",C26*0.373,IF($B26="SEP",C26*0.386,"")))))))))))) -> 1.5922107 | G26: =IF($D26="#","#",IF($B26="OCT",D26*0.373, IF($B26="NOV",D26*0.386,IF($B26="DIC",D26*0.373,IF($B26="ENE",D26*0.373,IF($B26="FEB",D26*0.413,IF($B26="MAR",D26*0.373,IF($B26="ABR",D26*0.386,IF($B26="MAY",D26*0.373,IF($B26="JUN",D26*0.386,IF($B26="JUL",D26*0.373,IF($B26="AGO",D26*0.373,IF($B26="SEP",D26*0.386,""))))))))))))) -> 1.0878293 | H26: =IF($B26="OCT",E26*0.373, IF($B26="NOV",E26*0.386,IF($B26="DIC",E26*0.373,IF($B26="ENE",E26*0.373,IF($B26="FEB",E26*0.413,IF($B26="MAR",E26*0.373,IF($B26="ABR",E26*0.386,IF($B26="MAY",E26*0.373,IF($B26="JUN",E26*0.386,IF($B26="JUL",E26*0.373,IF($B26="AGO",E26*0.373,IF($B26="SEP",E26*0.386,"")))))))))))) -> 0.81535145 | K26: =IF($B26="OCT",J26*0.373, IF($B26="NOV",J26*0.386,IF($B26="DIC",J26*0.373,IF($B26="ENE",J26*0.373,IF($B26="FEB",J26*0.413,IF($B26="MAR",J26*0.373,IF($B26="ABR",J26*0.386,IF($B26="MAY",J26*0.373,IF($B26="JUN",J26*0.386,IF($B26="JUL",J26*0.373,IF($B26="AGO",J26*0.373,IF($B26="SEP",J26*0.386,"")))))))))))) -> 0
B27: ='Informe nº 2'!M14 -> Nov | C27: 10.988697 | D27: 7.0796847 | E27: 3.9991102 | F27: =IF($B27="OCT",C27*0.373, IF($B27="NOV",C27*0.386,IF($B27="DIC",C27*0.373,IF($B27="ENE",C27*0.373,IF($B27="FEB",C27*0.413,IF($B27="MAR",C27*0.373,IF($B27="ABR",C27*0.386,IF($B27="MAY",C27*0.373,IF($B27="JUN",C27*0.386,IF($B27="JUL",C27*0.373,IF($B27="AGO",C27*0.373,IF($B27="SEP",C27*0.386,"")))))))))))) -> 4.2416371 | G27: =IF($D27="#","#",IF($B27="OCT",D27*0.373, IF($B27="NOV",D27*0.386,IF($B27="DIC",D27*0.373,IF($B27="ENE",D27*0.373,IF($B27="FEB",D27*0.413,IF($B27="MAR",D27*0.373,IF($B27="ABR",D27*0.386,IF($B27="MAY",D27*0.373,IF($B27="JUN",D27*0.386,IF($B27="JUL",D27*0.373,IF($B27="AGO",D27*0.373,IF($B27="SEP",D27*0.386,""))))))))))))) -> 2.7327583 | H27: =IF($B27="OCT",E27*0.373, IF($B27="NOV",E27*0.386,IF($B27="DIC",E27*0.373,IF($B27="ENE",E27*0.373,IF($B27="FEB",E27*0.413,IF($B27="MAR",E27*0.373,IF($B27="ABR",E27*0.386,IF($B27="MAY",E27*0.373,IF($B27="JUN",E27*0.386,IF($B27="JUL",E27*0.373,IF($B27="AGO",E27*0.373,IF($B27="SEP",E27*0.386,"")))))))))))) -> 1.5436565 | K27: =IF($B27="OCT",J27*0.373, IF($B27="NOV",J27*0.386,IF($B27="DIC",J27*0.373,IF($B27="ENE",J27*0.373,IF($B27="FEB",J27*0.413,IF($B27="MAR",J27*0.373,IF($B27="ABR",J27*0.386,IF($B27="MAY",J27*0.373,IF($B27="JUN",J27*0.386,IF($B27="JUL",J27*0.373,IF($B27="AGO",J27*0.373,IF($B27="SEP",J27*0.386,"")))))))))))) -> 0
B28: ='Informe nº 2'!N14 -> Dec | C28: 18.874857 | D28: 14.289956 | E28: 11.012544 | F28: =IF($B28="OCT",C28*0.373, IF($B28="NOV",C28*0.386,IF($B28="DIC",C28*0.373,IF($B28="ENE",C28*0.373,IF($B28="FEB",C28*0.413,IF($B28="MAR",C28*0.373,IF($B28="ABR",C28*0.386,IF($B28="MAY",C28*0.373,IF($B28="JUN",C28*0.386,IF($B28="JUL",C28*0.373,IF($B28="AGO",C28*0.373,IF($B28="SEP",C28*0.386,"")))))))))))) | G28: =IF($D28="#","#",IF($B28="OCT",D28*0.373, IF($B28="NOV",D28*0.386,IF($B28="DIC",D28*0.373,IF($B28="ENE",D28*0.373,IF($B28="FEB",D28*0.413,IF($B28="MAR",D28*0.373,IF($B28="ABR",D28*0.386,IF($B28="MAY",D28*0.373,IF($B28="JUN",D28*0.386,IF($B28="JUL",D28*0.373,IF($B28="AGO",D28*0.373,IF($B28="SEP",D28*0.386,""))))))))))))) | H28: =IF($B28="OCT",E28*0.373, IF($B28="NOV",E28*0.386,IF($B28="DIC",E28*0.373,IF($B28="ENE",E28*0.373,IF($B28="FEB",E28*0.413,IF($B28="MAR",E28*0.373,IF($B28="ABR",E28*0.386,IF($B28="MAY",E28*0.373,IF($B28="JUN",E28*0.386,IF($B28="JUL",E28*0.373,IF($B28="AGO",E28*0.373,IF($B28="SEP",E28*0.386,"")))))))))))) | K28: =IF($B28="OCT",J28*0.373, IF($B28="NOV",J28*0.386,IF($B28="DIC",J28*0.373,IF($B28="ENE",J28*0.373,IF($B28="FEB",J28*0.413,IF($B28="MAR",J28*0.373,IF($B28="ABR",J28*0.386,IF($B28="MAY",J28*0.373,IF($B28="JUN",J28*0.386,IF($B28="JUL",J28*0.373,IF($B28="AGO",J28*0.373,IF($B28="SEP",J28*0.386,""))))))))))))
B30: NOTE: For each month, for example October, the median contributions of wet, average and dry octubres are presented. Wet Octobers: Contributions are greater than or equal to the third quartile of the series of contributions in October. Dry Octobers: Contributions are less than or equal to the first quartile of the series of contributions in October. Average Octobers: Contributions fall between the first and third quartiles of the series of contributions in October. The values of the quartiles for each month can be consulted in report no.2 | J30: * Atypical Distribution of Monthly Typology: This occurs if the proportion of wet, average and dry months does not correspond to the normal patterns (25%, 50% and 25% respectively). In this case, the values A/B/C are used, where: A= no. of years in the series in which the month is wet. B= no. of years of the series in which the month is average. C= no. of years of the series in which the month is dry.
B36: # Cannot calculate

Sheet Informe nº3
B2: REPORT Nº 3 | E2: =UPPER(REPORTS!$AB$2) -> ALTERED FLOW | T2: MONTHLY CONTRIBUTIONS (hm3)
E3: CHARACTERIZATION OF THE INTRA-ANNUAL VARIABILITY (STATISTICS) | R3: STATISTICS | T3: =C14 -> Jan | U3: =D14 -> Feb | V3: =E14 -> Mar | W3: =F14 -> Apr | X3: =G14 -> May | Y3: =H14 -> Jun | Z3: =I14 -> Jul | AA3: =J14 -> Aug | ... AE3: =N14 -> Dec
R4: MINIMUM | T4: =MIN(C12:C612) -> 5.8532462 | U4: =MIN(D12:D612) -> 5.7766171 | V4: =MIN(E12:E612) -> 4.3456779 | W4: =MIN(F12:F612) -> 3.1278958 | X4: =MIN(G12:G612) -> 1.3168398 | Y4: =MIN(H12:H612) -> 0.37014538 | Z4: =MIN(I12:I612) -> 0.19043854 | AA4: =MIN(J12:J612) -> 0.13376534 | ... AE4: =MIN(N12:N612) -> 4.4008961
B5: NATURAL FLOW CODE (Abbreviation): | E5: =REPORTS!E7 -> Natural Flow (Nat_F) | R5: 75th percentile exceedance (P75) | T5: =_xlfn.PERCENTILE.EXC(C12:C612,0.25) -> 9.0476346 | U5: =_xlfn.PERCENTILE.EXC(D12:D612,0.25) -> 9.2640667 | V5: =_xlfn.PERCENTILE.EXC(E12:E612,0.25) -> 7.3309968 | W5: =_xlfn.PERCENTILE.EXC(F12:F612,0.25) -> 4.2609022 | X5: =_xlfn.PERCENTILE.EXC(G12:G612,0.25) -> 1.7469605 | Y5: =_xlfn.PERCENTILE.EXC(H12:H612,0.25) -> 0.48427197 | Z5: =_xlfn.PERCENTILE.EXC(I12:I612,0.25) -> 0.25078335 | AA5: =_xlfn.PERCENTILE.EXC(J12:J612,0.25) -> 0.16096148 | ... AE5: =_xlfn.PERCENTILE.EXC(N12:N612,0.25) -> 5.3573749
B6: ALTERED FLOW CODE (Abbreviation): | E6: =REPORTS!E8 -> Altered Flow (Alt_F) | R6: 50th percentile exceedance (P50) | T6: =_xlfn.PERCENTILE.EXC(C12:C612,0.5) -> 11.134283 | U6: =_xlfn.PERCENTILE.EXC(D12:D612,0.5) -> 10.854951 | V6: =_xlfn.PERCENTILE.EXC(E12:E612,0.5) -> 9.3216095 | W6: =_xlfn.PERCENTILE.EXC(F12:F612,0.5) -> 6.4912319 | X6: =_xlfn.PERCENTILE.EXC(G12:G612,0.5) -> 3.0271535 | Y6: =_xlfn.PERCENTILE.EXC(H12:H612,0.5) -> 0.64064729 | Z6: =_xlfn.PERCENTILE.EXC(I12:I612,0.5) -> 0.32523811 | AA6: =_xlfn.PERCENTILE.EXC(J12:J612,0.5) -> 0.19344787 | ... AE6: =_xlfn.PERCENTILE.EXC(N12:N612,0.5) -> 6.681139
B7: DATE: | E7: 18/05/2026 | R7: MEAN | T7: =AVERAGE(C12:C612) -> 11.055148 | U7: =AVERAGE(D12:D612) -> 11.588573 | V7: =AVERAGE(E12:E612) -> 9.3487192 | W7: =AVERAGE(F12:F612) -> 6.2882484 | X7: =AVERAGE(G12:G612) -> 3.1499466 | Y7: =AVERAGE(H12:H612) -> 0.70254871 | Z7: =AVERAGE(I12:I612) -> 0.31675359 | AA7: =AVERAGE(J12:J612) -> 0.19891572 | ... AE7: =AVERAGE(N12:N612) -> 6.9098148
R8: 25th percentile exceedance (P25) | T8: =_xlfn.PERCENTILE.EXC(C12:C612,0.75) -> 13.097288 | U8: =_xlfn.PERCENTILE.EXC(D12:D612,0.75) -> 14.13396 | V8: =_xlfn.PERCENTILE.EXC(E12:E612,0.75) -> 10.797235 | W8: =_xlfn.PERCENTILE.EXC(F12:F612,0.75) -> 7.8829632 | X8: =_xlfn.PERCENTILE.EXC(G12:G612,0.75) -> 3.8976856 | Y8: =_xlfn.PERCENTILE.EXC(H12:H612,0.75) -> 0.81301099 | Z8: =_xlfn.PERCENTILE.EXC(I12:I612,0.75) -> 0.36814824 | AA8: =_xlfn.PERCENTILE.EXC(J12:J612,0.75) -> 0.22766569 | ... AE8: =_xlfn.PERCENTILE.EXC(N12:N612,0.75) -> 8.1166329
R9: MAXIMUM | T9: =MAX(C12:C612) -> 19.188316 | U9: =MAX(D12:D612) -> 17.723316 | V9: =MAX(E12:E612) -> 15.186528 | W9: =MAX(F12:F612) -> 10.988006 | X9: =MAX(G12:G612) -> 8.1127882 | Y9: =MAX(H12:H612) -> 1.6174858 | Z9: =MAX(I12:I612) -> 0.56505591 | AA9: =MAX(J12:J612) -> 0.31778792 | ... AE9: =MAX(N12:N612) -> 10.494664
R10: INTERQUARTILE RANGE | T10: =T8-T5 -> 4.0496535 | U10: =U8-U5 -> 4.8698931 | V10: =V8-V5 -> 3.4662383 | W10: =W8-W5 -> 3.622061 | X10: =X8-X5 -> 2.1507252 | Y10: =Y8-Y5 -> 0.32873902 | Z10: =Z8-Z5 -> 0.11736488 | AA10: =AA8-AA5 -> 0.066704214 | ... AE10: =AE8-AE5 -> 2.759258
R11: Coefficient of variation | T11: =_xlfn.STDEV.S(C12:C612) -> 3.3690733 | U11: =_xlfn.STDEV.S(D12:D612) -> 3.3024536 | V11: =_xlfn.STDEV.S(E12:E612) -> 2.5945899 | W11: =_xlfn.STDEV.S(F12:F612) -> 2.1523625 | X11: =_xlfn.STDEV.S(G12:G612) -> 1.6932627 | Y11: =_xlfn.STDEV.S(H12:H612) -> 0.30074457 | Z11: =_xlfn.STDEV.S(I12:I612) -> 0.086853967 | AA11: =_xlfn.STDEV.S(J12:J612) -> 0.043416461 | ... AE11: =_xlfn.STDEV.S(N12:N612) -> 1.8551474
R12: Coefficient of skewness | T12: =SKEW(C12:C612) -> 0.50662861 | U12: =SKEW(D12:D612) -> 0.28169622 | V12: =SKEW(E12:E612) -> 0.18561889 | W12: =SKEW(F12:F612) -> 0.2312096 | X12: =SKEW(G12:G612) -> 1.4554946 | Y12: =SKEW(H12:H612) -> 1.6663518 | Z12: =SKEW(I12:I612) -> 0.95645548 | AA12: =SKEW(J12:J612) -> 0.75947702 | ... AE12: =SKEW(N12:N612) -> 0.45293687
B13: YEAR | C13: MONTHLY CONTRIBUTION (hm3) | O13: Extreme variability
C14: Jan | D14: Feb | E14: Mar | F14: Apr | G14: May | H14: Jun | I14: Jul | J14: Aug | K14: Sep | L14: Oct | M14: Nov | N14: Dec
B15: 2080 | C15: 5.8532462 | D15: 11.145254 | E15: 15.186528 | F15: 10.988006 | G15: 5.9963336 | H15: 1.263384 | I15: 0.42952034 | J15: 0.24439271 | K15: 0.19109344 | L15: 0.46813071 | M15: 5.0125051 | N15: 6.2942405 | O15: =MAX(C15:N15) - MIN(C15:N15) -> 14.995435 | T15: RELATIVE FREQUENCIES
B16: 2081 | C16: 9.8762121 | D16: 9.1097565 | E16: 6.0758214 | F16: 4.3477688 | G16: 2.2519643 | H16: 0.49244541 | I16: 0.22985509 | J16: 0.15357429 | K16: 0.15724972 | L16: 2.1457951 | M16: 4.8785758 | N16: 9.3898659 | O16: =MAX(C16:N16) - MIN(C16:N16) -> 9.7226378 | T16: =C14 -> Jan | U16: =D14 -> Feb | V16: =E14 -> Mar | W16: =F14 -> Apr | X16: =G14 -> May | Y16: =H14 -> Jun | Z16: =I14 -> Jul | AA16: =J14 -> Aug | ... AE16: =N14 -> Dec
B17: 2082 | C17: 9.4327192 | D17: 10.738139 | E17: 9.5357084 | F17: 8.0631943 | G17: 3.898766 | H17: 0.84741116 | I17: 0.3674376 | J17: 0.22871201 | K17: 0.18377884 | L17: 0.58639938 | M17: 2.7863052 | N17: 7.1623869 | O17: =MAX(C17:N17) - MIN(C17:N17) -> 10.55436 | R17: Maximum monthly contribution | T17: 0.47619048 | U17: 0.38095239 | V17: 0.14285715 | W17: 0 | X17: 0 | Y17: 0 | Z17: 0 | AA17: 0 | AB17: 0 | AC17: 0 | AD17: 0 | AE17: 0
B18: 2083 | C18: 11.134283 | D18: 15.322004 | E18: 9.2855787 | F18: 7.9134622 | G18: 8.1127882 | H18: 1.6174858 | I18: 0.56505591 | J18: 0.31778792 | K18: 0.39530849 | L18: 1.4682791 | M18: 4.8367586 | N18: 9.1820736 | O18: =MAX(C18:N18) - MIN(C18:N18) -> 15.004216 | R18: Minimum monthly contribution | T18: 0 | U18: 0 | V18: 0 | W18: 0 | X18: 0 | Y18: 0 | Z18: 0 | AA18: 0.2857143 | AB18: 0.71428573 | AC18: 0 | AD18: 0 | AE18: 0
B19: 2084 | C19: 16.027027 | D19: 14.678148 | E19: 12.107924 | F19: 6.2122464 | G19: 2.7656295 | H19: 0.683882 | I19: 0.34505135 | J19: 0.2329111 | K19: 0.21562849 | L19: 2.0616016 | M19: 4.9747219 | N19: 10.494664 | O19: =MAX(C19:N19) - MIN(C19:N19) -> 15.811399
B20: 2085 | C20: 13.651628 | D20: 13.450234 | E20: 5.9740415 | F20: 4.6446738 | G20: 3.0271535 | H20: 0.60496414 | I20: 0.29103151 | J20: 0.19005321 | K20: 0.14693703 | L20: 0.77913356 | M20: 2.1514289 | N20: 5.6621642 | O20: =MAX(C20:N20) - MIN(C20:N20) -> 13.504691
B21: 2086 | C21: 8.8171196 | D21: 12.618202 | E21: 12.376887 | F21: 7.1308517 | G21: 1.7184877 | H21: 0.53262144 | I21: 0.28113699 | J21: 0.18266863 | K21: 0.15537831 | L21: 1.249566 | M21: 3.7372754 | N21: 10.240266 | O21: =MAX(C21:N21) - MIN(C21:N21) -> 12.462824 | T21: =T3 -> Jan | U21: =U3 -> Feb | V21: =V3 -> Mar | W21: =W3 -> Apr | X21: =X3 -> May | Y21: =Y3 -> Jun | Z21: =Z3 -> Jul | AA21: =AA3 -> Aug | ... AE21: =AE3 -> Dec | AG21: =CONCATENATE("MONTHLY CONTRIBUTIONS IN ",UPPER(REPORTS!$AB$2)," (hm³)") -> MONTHLY CONTRIBUTIONS IN ALTERED FLOW (hm³)
B22: 2087 | C22: 19.188316 | D22: 17.560453 | E22: 10.894953 | F22: 6.0397911 | G22: 2.3536911 | H22: 0.61531484 | I22: 0.33407599 | J22: 0.2238391 | K22: 0.25941429 | L22: 0.76281089 | M22: 3.3895669 | N22: 4.780745 | O22: =MAX(C22:N22) - MIN(C22:N22) -> 18.964477 | S22: Q1 (P25%) | T22: =T5 -> 9.0476346 | U22: =U5 -> 9.2640667 | V22: =V5 -> 7.3309968 | W22: =W5 -> 4.2609022 | X22: =X5 -> 1.7469605 | Y22: =Y5 -> 0.48427197 | Z22: =Z5 -> 0.25078335 | AA22: =AA5 -> 0.16096148 | ... AE22: =AE5 -> 5.3573749
